<!-- -->
<robot name="cyton_arm">

  <link name="base" />
  <link name="shoulder" />
  <link name="shoulder_arm" />
  <link name="arm" />
  <link name="elbow" />
  <link name="forearm" />
  <link name="wrist" />
  <link name="hand" />
  <link name="grip" />
  <link name="finger" />
  <link name="fingertip" />

  <joint name="joint1" type="fixed">
    <parent link="base"/>
    <child link="shoulder"/>
    <origin xyz="0 0 0" rpy="0 0 0" />
  </joint>

  <joint name="joint2" type="revolute">
    <parent link="shoulder"/>
    <child link="shoulder_arm"/>
    <origin xyz="0 0.1 0" rpy="0 0 0" />
    <axis xyz ="1 0 0"/>
    <limit effort="124.016" velocity="12" lower="-0.610865" upper="0.610865" />
  </joint>

  <joint name="joint3" type="revolute">
    <parent link="shoulder_arm"/>
    <child link="arm"/>
    <origin xyz="0 0.035 0" rpy="0 0 0" />
    <axis xyz ="1 0 0"/>
    <limit effort="124.016" velocity="12" lower="-0.610865" upper="0.610865" />
  </joint>

  <joint name="joint4" type="revolute">
    <parent link="arm"/>
    <child link="elbow"/>
    <origin xyz="0 0.125 0" rpy="0 0 0" />
    <axis xyz ="1 0 0"/>
    <limit effort="124.016" velocity="12" lower="-0.610865" upper="0.610865" />
  </joint>

  <joint name="joint5" type="revolute">
    <parent link="elbow"/>
    <child link="forearm"/>
    <origin xyz="0 0.028 0" rpy="0 0 0" />
    <axis xyz ="1 0 0"/>
    <limit effort="124.016" velocity="12" lower="-0.610865" upper="0.610865" />
  </joint>

  <joint name="joint6" type="revolute">
    <parent link="forearm"/>
    <child link="wrist"/>
    <origin xyz="0 0.103 0" rpy="0 0 0" />
    <axis xyz ="1 0 0"/>
    <limit effort="124.016" velocity="12" lower="-0.610865" upper="0.610865" />
  </joint>

  <joint name="joint7" type="revolute">
    <parent link="wrist"/>
    <child link="hand"/>
    <origin xyz="0 0.054 0" rpy="0 0 0" />
    <axis xyz ="1 0 0"/>
    <limit effort="124.016" velocity="12" lower="-0.610865" upper="0.610865" />
  </joint>

  <joint name="joint8" type="revolute">
    <parent link="hand"/>
    <child link="grip"/>
    <origin xyz="0 0.065 0" rpy="0 0 0" />
    <axis xyz ="1 0 0"/>
    <limit effort="124.016" velocity="12" lower="-0.610865" upper="0.610865" />
  </joint>

  <joint name="joint9" type="prismatic">
    <parent link="grip"/>
    <child link="finger"/>
    <origin xyz="0 0.035 0" rpy="1.57079632679 0 0" />
    <axis xyz ="1 0 0"/>
    <limit effort="124.016" velocity="12" lower="-0.610865" upper="0.610865" />
  </joint>

  <joint name="joint10" type="fixed">
    <parent link="finger"/>
    <child link="fingertip"/>
    <origin xyz="0 0.04 0" rpy="0 0 0" />
  </joint>
</robot>
